<sdf version='1.12'>
  <model name='export_ready_assembly_v1'>
    <link name='base_link'>
      <inertial>
        <mass>0.0001</mass>
        <inertia>
          <ixx>1.0000000000000001e-09</ixx>
          <ixy>0</ixy>
          <ixz>0</ixz>
          <iyy>1.0000000000000001e-09</iyy>
          <iyz>0</iyz>
          <izz>1.0000000000000001e-09</izz>
        </inertia>
      </inertial>
    </link>
    <link name='base_link_1'>
      <pose relative_to='__model__'>0 0 0.012500000000000002 0 0 1.570796326794897</pose>
      <inertial>
        <pose>1.9219946611189295e-18 3.0751914577902847e-17 1.7347234759768071e-18 0 0 -1.570796326794897</pose>
        <mass>0.19963274876480658</mass>
        <inertia>
          <ixx>3.3908296797800469e-05</ixx>
          <ixy>-5.5442699342783073e-19</ixy>
          <ixz>-6.1390892369672742e-20</ixz>
          <iyy>0.0015141997641349501</iyy>
          <iyz>1.1510792319313615e-20</iyz>
          <izz>0.0015141997641349469</izz>
        </inertia>
      </inertial>
      <visual name='base_link_1__body1_visual'>
        <geometry>
          <mesh>
            <scale>0.01 0.01 0.01</scale>
            <uri>meshes/base_link_1/body1_visual.obj</uri>
          </mesh>
        </geometry>
      </visual>
      <collision name='base_link_1__body1_collision'>
        <pose relative_to='__model__'>0 4.8849813083506888e-17 0.012500000000000002 0 -1.5707963267948966 0</pose>
        <geometry>
          <box>
            <size>0.025000000000000001 0.025000000000000001 0.29999999999999999</size>
          </box>
        </geometry>
      </collision>
    </link>
    <link name='base_structure_v3_1'>
      <inertial>
        <pose>-9.2688038443831307e-05 -0.0043581079639150059 0.14279087376672875 0 0 0</pose>
        <mass>4.7661048317642321</mass>
        <inertia>
          <ixx>0.22272563316699104</ixx>
          <ixy>1.9260060529486026e-06</ixy>
          <ixz>-1.674401404712093e-06</ixz>
          <iyy>0.12062612871567982</iyy>
          <iyz>8.063758586629487e-05</iyz>
          <izz>0.28749380795747226</izz>
        </inertia>
      </inertial>
      <visual name='base_structure_v3_1__body1_visual'>
        <geometry>
          <mesh>
            <scale>0.01 0.01 0.01</scale>
            <uri>meshes/base_structure_v3_1/body1_visual.obj</uri>
          </mesh>
        </geometry>
      </visual>
      <collision name='base_structure_v3_1__body1_collision'>
        <pose relative_to='__model__'>-2.2351740014414647e-09 -0.0050000000000000001 0.13750000176951302 0 -1.5707963267948966 0</pose>
        <geometry>
          <box>
            <size>0.27500000353902604 0.60999999999999999 0.36000000521540604</size>
          </box>
        </geometry>
      </collision>
    </link>
    <link name='aft_support_1'>
      <pose relative_to='__model__'>-1.2172316843361841e-09 0.2875000000000002 0.012500001034329604 6.895530703326297e-09 6.1232336425403799e-17 1.5707963267948963</pose>
      <inertial>
        <pose>-7.6540434905757263e-19 -3.3684988808297894e-17 -1.1975023400258026e-18 6.1232336838994105e-17 -6.895530703326297e-09 -1.5707963267948963</pose>
        <mass>0.18224999999999994</mass>
        <inertia>
          <ixx>2.937295320220093e-05</ixx>
          <ixy>1.8417266811372659e-19</ixy>
          <ixz>9.3240575411734428e-12</ixz>
          <iyy>0.001381561476601102</iyy>
          <iyz>0</iyz>
          <izz>0.0013815614766010988</izz>
        </inertia>
      </inertial>
      <visual name='aft_support_1__body1_visual'>
        <geometry>
          <mesh>
            <scale>0.01 0.01 0.01</scale>
            <uri>meshes/aft_support_1/body1_visual.obj</uri>
          </mesh>
        </geometry>
      </visual>
      <collision name='aft_support_1__body1_collision'>
        <pose relative_to='__model__'>-1.2948063954354438e-09 0.2875000000000002 0.012500000000000001 0 -1.5707963267948966 0</pose>
        <geometry>
          <box>
            <size>0.025000000000000001 0.025000000000000001 0.30000000001723881</size>
          </box>
        </geometry>
      </collision>
    </link>
    <link name='aft_support_2'>
      <pose relative_to='__model__'>-1.2172317376268894e-09 -0.28749999999999998 0.012500001034329604 6.8955307033262987e-09 -3.3087224502121107e-24 1.5707963267948968</pose>
      <inertial>
        <pose>2.3930154424120435e-25 -3.368498915886532e-17 -1.4545640007087047e-18 -2.481541837659083e-24 -6.8955307033262987e-09 -1.5707963267948968</pose>
        <mass>0.18224999999999994</mass>
        <inertia>
          <ixx>2.937295320220093e-05</ixx>
          <ixy>1.0137500364916267e-19</ixy>
          <ixz>9.3240575411734428e-12</ixz>
          <iyy>0.001381561476601102</iyy>
          <iyz>1.0842021724855044e-19</iyz>
          <izz>0.0013815614766011005</izz>
        </inertia>
      </inertial>
      <visual name='aft_support_2__body1_visual'>
        <geometry>
          <mesh>
            <scale>0.01 0.01 0.01</scale>
            <uri>meshes/aft_support_2/body1_visual.obj</uri>
          </mesh>
        </geometry>
      </visual>
      <collision name='aft_support_2__body1_collision'>
        <pose relative_to='__model__'>-1.294806448726149e-09 -0.28749999999999998 0.012499999999999997 0 -1.5707963267948966 0</pose>
        <geometry>
          <box>
            <size>0.025000000000000001 0.025000000000000001 0.30000000001723881</size>
          </box>
        </geometry>
      </collision>
    </link>
    <link name='batt_hull_v1_1'>
      <pose relative_to='__model__'>0.00099999776482604828 0.078125000000000014 0.08500000182539201 0 0 -1.5707963267948963</pose>
      <inertial>
        <pose>6.123220309243801e-20 2.6467820008879437e-17 0 0 0 1.5707963267948963</pose>
        <mass>0.8210866559422294</mass>
        <inertia>
          <ixx>0.0025043143006237625</ixx>
          <ixy>-6.7762635780344027e-20</ixy>
          <ixz>0</ixz>
          <iyy>0.0039891126701192721</iyy>
          <iyz>0</iyz>
          <izz>0.003989112670119338</izz>
        </inertia>
      </inertial>
      <visual name='batt_hull_v1_1__body1_visual'>
        <geometry>
          <mesh>
            <scale>0.01 0.01 0.01</scale>
            <uri>meshes/batt_hull_v1_1/body1_visual.obj</uri>
          </mesh>
        </geometry>
      </visual>
      <collision name='batt_hull_v1_1__body1_collision'>
        <pose relative_to='__model__'>0.00099999776482604828 0.078125 0.08500000182539201 0 -1.5707963267948966 0</pose>
        <geometry>
          <box>
            <size>0.12 0.12 0.20000000000000001</size>
          </box>
        </geometry>
      </collision>
    </link>
    <link name='lower_mounts_v4_1'>
      <pose relative_to='__model__'>-0.075000002235174001 0 0.015000001825392016 0 0 -1.5707963267948963</pose>
      <inertial>
        <pose>-1.122951742896557e-14 6.8760962876760502e-31 0.059830004860879013 0 0 1.5707963267948963</pose>
        <mass>0.20889715202694284</mass>
        <inertia>
          <ixx>0.0014043910383185222</ixx>
          <ixy>2.1537388909222726e-22</ixy>
          <ixz>0</ixz>
          <iyy>0.00034258494964595036</iyy>
          <iyz>2.6515377067311625e-15</iyz>
          <izz>0.0010787257693986127</izz>
        </inertia>
      </inertial>
      <visual name='lower_mounts_v4_1__body1_visual'>
        <geometry>
          <mesh>
            <scale>0.01 0.01 0.01</scale>
            <uri>meshes/lower_mounts_v4_1/body1_visual.obj</uri>
          </mesh>
        </geometry>
      </visual>
      <collision name='lower_mounts_v4_1__body1_collision'>
        <pose relative_to='__model__'>-0.075000002235174001 0 0.075000001825392029 0 -1.5707963267948966 0</pose>
        <geometry>
          <box>
            <size>0.12 0.28625 0.022000000000000002</size>
          </box>
        </geometry>
      </collision>
    </link>
    <link name='lower_mounts_v4_2'>
      <pose relative_to='__model__'>0.075000001490116291 0 0.015000001825392016 0 0 1.5707963267948963</pose>
      <inertial>
        <pose>-1.122951742896557e-14 -1.3877787807815144e-17 0.059830004860879013 0 0 -1.5707963267948963</pose>
        <mass>0.20889715202694284</mass>
        <inertia>
          <ixx>0.0014043910383185222</ixx>
          <ixy>-1.2981836889172902e-19</ixy>
          <ixz>0</ixz>
          <iyy>0.00034258494964595036</iyy>
          <iyz>-2.6515377067311625e-15</iyz>
          <izz>0.001078725769398613</izz>
        </inertia>
      </inertial>
      <visual name='lower_mounts_v4_2__body1_visual'>
        <geometry>
          <mesh>
            <scale>0.01 0.01 0.01</scale>
            <uri>meshes/lower_mounts_v4_2/body1_visual.obj</uri>
          </mesh>
        </geometry>
      </visual>
      <collision name='lower_mounts_v4_2__body1_collision'>
        <pose relative_to='__model__'>0.075000001490116305 0 0.075000001825392029 0 -1.5707963267948966 0</pose>
        <geometry>
          <box>
            <size>0.12 0.28625 0.022000000000000009</size>
          </box>
        </geometry>
      </collision>
    </link>
    <link name='batt_hull_2_1'>
      <pose relative_to='__model__'>0.00099999776482604828 -0.078125000000000028 0.08500000182539201 0 0 -1.5707963267948963</pose>
      <inertial>
        <pose>6.123220309243801e-20 2.6441246008413177e-17 0 0 0 1.5707963267948963</pose>
        <mass>0.8210866559422294</mass>
        <inertia>
          <ixx>0.0025043143006237625</ixx>
          <ixy>-9.4867690092481638e-20</ixy>
          <ixz>0</ixz>
          <iyy>0.0039891126701192721</iyy>
          <iyz>1.7347234759768071e-18</iyz>
          <izz>0.0039891126701193397</izz>
        </inertia>
      </inertial>
      <visual name='batt_hull_2_1__body1_visual'>
        <geometry>
          <mesh>
            <scale>0.01 0.01 0.01</scale>
            <uri>meshes/batt_hull_2_1/body1_visual.obj</uri>
          </mesh>
        </geometry>
      </visual>
      <collision name='batt_hull_2_1__body1_collision'>
        <pose relative_to='__model__'>0.00099999776482604828 -0.078125000000000042 0.08500000182539201 0 -1.5707963267948966 0</pose>
        <geometry>
          <box>
            <size>0.12 0.12 0.20000000000000001</size>
          </box>
        </geometry>
      </collision>
    </link>
    <link name='thruster_enclosure_v5_1'>
      <pose relative_to='__model__'>0.10217830048637019 -0.20407169914110088 0.075000000858279001 -1.5707963267948963 0 2.3561944901923448</pose>
      <inertial>
        <pose>-0.00016404096371552097 -0.016890935437908081 0.010727722238094154 -1.5707963267948963 0.78539816339744817 -3.1415926535897931</pose>
        <mass>0.16043165212635116</mass>
        <inertia>
          <ixx>0.00036276346356354898</ixx>
          <ixy>6.5704249860997974e-05</ixy>
          <ixz>-6.255743962602393e-06</ixz>
          <iyy>0.00036315916999338964</iyy>
          <iyz>-6.101982790084233e-06</iyz>
          <izz>0.00028918540189159375</izz>
        </inertia>
      </inertial>
      <visual name='thruster_enclosure_v5_1__body1_visual'>
        <geometry>
          <mesh>
            <scale>0.01 0.01 0.01</scale>
            <uri>meshes/thruster_enclosure_v5_1/body1_visual.obj</uri>
          </mesh>
        </geometry>
      </visual>
      <collision name='thruster_enclosure_v5_1__body1_collision'>
        <pose relative_to='__model__'>0.09705177645678667 -0.20919822343306332 0.078750000911123455 -0.78539816273052721 -1.5707963267948966 0</pose>
        <geometry>
          <box>
            <size>0.1124999998596319 0.13999999998249063 0.11450000001676784</size>
          </box>
        </geometry>
      </collision>
    </link>
    <link name='thruster_enclosure_v5_2'>
      <pose relative_to='__model__'>-0.10217830123142801 -0.20407169914110093 0.075000000974184994 -1.5707963267948968 1.1102230246251565e-16 -2.3561944901923448</pose>
      <inertial>
        <pose>-0.00016404096371552219 -0.016890935437908056 0.010727722238094154 -1.5707963267948966 -0.7853981633974485 3.1415926535897931</pose>
        <mass>0.16043165212635116</mass>
        <inertia>
          <ixx>0.00036315916999339094</ixx>
          <ixy>-6.5704249860998407e-05</ixy>
          <ixz>6.101982790084233e-06</ixz>
          <iyy>0.00036276346356354724</iyy>
          <iyz>-6.2557439626030435e-06</iyz>
          <izz>0.00028918540189159549</izz>
        </inertia>
      </inertial>
      <visual name='thruster_enclosure_v5_2__body1_visual'>
        <geometry>
          <mesh>
            <scale>0.01 0.01 0.01</scale>
            <uri>meshes/thruster_enclosure_v5_2/body1_visual.obj</uri>
          </mesh>
        </geometry>
      </visual>
      <collision name='thruster_enclosure_v5_2__body1_collision'>
        <pose relative_to='__model__'>-0.097051777189819083 -0.20919822342103792 0.078750001043543363 -0.78539816273052721 -1.5707963267948966 0</pose>
        <geometry>
          <box>
            <size>0.1124999998926597 0.11450000001676783 0.14000000001750937</size>
          </box>
        </geometry>
      </collision>
    </link>
    <link name='thruster_enclosure_v5_3'>
      <pose relative_to='__model__'>-0.10217830123142782 0.20407169914110093 0.074999998717278957 -1.5707963267948946 -2.2759572004815709e-15 -0.78539816339744606</pose>
      <inertial>
        <pose>-0.00016404096371550435 -0.016890935437908056 0.010727722238094119 1.5707963267948937 -0.78539816339744617 4.2392496384461827e-15</pose>
        <mass>0.16043165212635116</mass>
        <inertia>
          <ixx>0.00036276346356354724</ixx>
          <ixy>6.5704249860997106e-05</ixy>
          <ixz>6.255743962602393e-06</ixz>
          <iyy>0.00036315916999338921</iyy>
          <iyz>6.101982790084233e-06</iyz>
          <izz>0.00028918540189159375</izz>
        </inertia>
      </inertial>
      <visual name='thruster_enclosure_v5_3__body1_visual'>
        <geometry>
          <mesh>
            <scale>0.01 0.01 0.01</scale>
            <uri>meshes/thruster_enclosure_v5_3/body1_visual.obj</uri>
          </mesh>
        </geometry>
      </visual>
      <collision name='thruster_enclosure_v5_3__body1_collision'>
        <pose relative_to='__model__'>-0.097051777201844477 0.20919822343306355 0.078749998770123439 -0.7853981627305292 -1.5707963267948966 0</pose>
        <geometry>
          <box>
            <size>0.11249999985963187 0.13999999998249063 0.1145000000167678</size>
          </box>
        </geometry>
      </collision>
    </link>
    <link name='thruster_enclosure_v5_4'>
      <pose relative_to='__model__'>0.10217830048637012 0.20407169914110093 0.074999998717279054 -1.5707963267948959 -1.8318679906315083e-15 0.78539816339744761</pose>
      <inertial>
        <pose>-0.00016404096371555902 -0.016890935437908056 0.010727722238094116 1.5707963267948957 0.78539816339744795 1.2560739669470188e-15</pose>
        <mass>0.16043165212635116</mass>
        <inertia>
          <ixx>0.00036315916999339094</ixx>
          <ixy>-6.5704249860997106e-05</ixy>
          <ixz>-6.1019827900837993e-06</ixz>
          <iyy>0.00036276346356354681</iyy>
          <iyz>6.2557439626021762e-06</iyz>
          <izz>0.00028918540189159549</izz>
        </inertia>
      </inertial>
      <visual name='thruster_enclosure_v5_4__body1_visual'>
        <geometry>
          <mesh>
            <scale>0.01 0.01 0.01</scale>
            <uri>meshes/thruster_enclosure_v5_4/body1_visual.obj</uri>
          </mesh>
        </geometry>
      </visual>
      <collision name='thruster_enclosure_v5_4__body1_collision'>
        <pose relative_to='__model__'>0.097051776444761192 0.20919822342103797 0.07874999878663741 -0.78539816273052676 -1.5707963267948966 0</pose>
        <geometry>
          <box>
            <size>0.11249999989265967 0.1145000000167678 0.14000000001750934</size>
          </box>
        </geometry>
      </collision>
    </link>
    <link name='main_hull_mounts_v2_1'>
      <pose relative_to='__model__'>-1.8652000832730663e-10 0 0.16000000159752886 0 0 0</pose>
      <inertial>
        <pose>0 0 0.033932154244340623 0 0 0</pose>
        <mass>0.62436572706623128</mass>
        <inertia>
          <ixx>0.00037968794747304108</ixx>
          <ixy>-2.5920599000528452e-19</ixy>
          <ixz>5.1841198413007744e-19</ixz>
          <iyy>0.0066532809466919134</iyy>
          <iyz>-3.2400748750660565e-20</iyz>
          <izz>0.0063386310957882731</izz>
        </inertia>
      </inertial>
      <visual name='main_hull_mounts_v2_1__body1_visual'>
        <geometry>
          <mesh>
            <scale>0.01 0.01 0.01</scale>
            <uri>meshes/main_hull_mounts_v2_1/body1_visual.obj</uri>
          </mesh>
        </geometry>
      </visual>
      <collision name='main_hull_mounts_v2_1__body1_collision'>
        <pose relative_to='__model__'>-1.8652000832730663e-10 0 0.20500000159752887 0 -1.5707963267948966 0</pose>
        <geometry>
          <box>
            <size>0.089999999999999997 0.025000000000000001 0.29999999999999999</size>
          </box>
        </geometry>
      </collision>
    </link>
    <link name='main_hull_mounts_v2_2'>
      <pose relative_to='__model__'>-1.863496549410039e-10 -0.14374999999999999 0.16000000182539204 0 0 6.123233995736766e-17</pose>
      <inertial>
        <pose>-3.6566183554762268e-27 1.1410625422285708e-26 0.033932154244340595 0 0 -6.123233995736766e-17</pose>
        <mass>0.62436572706623128</mass>
        <inertia>
          <ixx>0.00037968794747305495</ixx>
          <ixy>-6.4335277535715913e-19</ixy>
          <ixz>5.1841198413007744e-19</ixz>
          <iyy>0.0066532809466919238</iyy>
          <iyz>3.4694469519536142e-18</iyz>
          <izz>0.0063386310957882757</izz>
        </inertia>
      </inertial>
      <visual name='main_hull_mounts_v2_2__body1_visual'>
        <geometry>
          <mesh>
            <scale>0.01 0.01 0.01</scale>
            <uri>meshes/main_hull_mounts_v2_2/body1_visual.obj</uri>
          </mesh>
        </geometry>
      </visual>
      <collision name='main_hull_mounts_v2_2__body1_collision'>
        <pose relative_to='__model__'>-1.8634965570640816e-10 -0.14374999999999999 0.20500000182539202 0 -1.5707963267948966 0</pose>
        <geometry>
          <box>
            <size>0.089999999999999997 0.025000000000000001 0.29999999999999999</size>
          </box>
        </geometry>
      </collision>
    </link>
    <link name='main_hull_mounts_v2_3'>
      <pose relative_to='__model__'>-1.86349638708244e-10 0.14375000000000002 0.16000000182539204 -7.2513657160497234e-33 -1.1842378914636296e-16 6.123233995736766e-17</pose>
      <inertial>
        <pose>2.2362970986363366e-26 1.1410623268097308e-26 0.033932154244340595 0 1.1842378914636296e-16 -6.123233995736766e-17</pose>
        <mass>0.62436572706623128</mass>
        <inertia>
          <ixx>0.00037968794747305495</ixx>
          <ixy>-6.4335276566363632e-19</ixy>
          <ixz>-1.8726864358779919e-19</ixz>
          <iyy>0.0066532809466919238</iyy>
          <iyz>0</iyz>
          <izz>0.006338631095788274</izz>
        </inertia>
      </inertial>
      <visual name='main_hull_mounts_v2_3__body1_visual'>
        <geometry>
          <mesh>
            <scale>0.01 0.01 0.01</scale>
            <uri>meshes/main_hull_mounts_v2_3/body1_visual.obj</uri>
          </mesh>
        </geometry>
      </visual>
      <collision name='main_hull_mounts_v2_3__body1_collision'>
        <pose relative_to='__model__'>-1.8634965570640816e-10 0.14375000000000004 0.20500000182539202 0 -1.5707963267948966 0</pose>
        <geometry>
          <box>
            <size>0.089999999999999997 0.024999999999999981 0.29999999999999999</size>
          </box>
        </geometry>
      </collision>
    </link>
    <link name='main_hull_v2_1'>
      <pose relative_to='__model__'>-1.8652000832730663e-10 0.012500000000000001 0.32500000159752884 0 0 0</pose>
      <inertial>
        <mass>7.1498721804886785</mass>
        <inertia>
          <ixx>0.20727181539895523</ixx>
          <ixy>2.7706846593151522e-17</ixy>
          <ixz>1.0339757656912846e-25</ixz>
          <iyy>0.11663228994421992</iyy>
          <iyz>2.0816681711721685e-17</iyz>
          <izz>0.20727181539895856</izz>
        </inertia>
      </inertial>
      <visual name='main_hull_v2_1__body1_visual'>
        <geometry>
          <mesh>
            <scale>0.01 0.01 0.01</scale>
            <uri>meshes/main_hull_v2_1/body1_visual.obj</uri>
          </mesh>
        </geometry>
      </visual>
      <collision name='main_hull_v2_1__body1_collision'>
        <pose relative_to='__model__'>-1.8652000832730663e-10 0.012500000000000001 0.32500000159752884 0 -1.5707963267948966 0</pose>
        <geometry>
          <box>
            <size>0.27000000000000002 0.5 0.27000000000000002</size>
          </box>
        </geometry>
      </collision>
    </link>
    <link name='secondary_hull_endcaps_v1_1'>
      <pose relative_to='__model__'>-0.099000002235173953 -0.078125000000000042 0.08500000182539201 0 0 -1.5707963267948963</pose>
      <inertial>
        <pose>-6.117211279491137e-18 -0.00090163934426229974 0 0 0 1.5707963267948963</pose>
        <mass>0.2730829414132927</mass>
        <inertia>
          <ixx>0.00042999371348764574</ixx>
          <ixy>0</ixy>
          <ixz>0</ixz>
          <iyy>0.00022387761772263599</iyy>
          <iyz>-2.1684043449710089e-19</iyz>
          <izz>0.00022387761772264727</izz>
        </inertia>
      </inertial>
      <visual name='secondary_hull_endcaps_v1_1__body1_visual'>
        <geometry>
          <mesh>
            <scale>0.01 0.01 0.01</scale>
            <uri>meshes/secondary_hull_endcaps_v1_1/body1_visual.obj</uri>
          </mesh>
        </geometry>
      </visual>
      <collision name='secondary_hull_endcaps_v1_1__body1_collision'>
        <pose relative_to='__model__'>-0.099000002235173953 -0.078125000000000042 0.08500000182539201 0 -1.5707963267948966 0</pose>
        <geometry>
          <box>
            <size>0.12 0.12 0.02</size>
          </box>
        </geometry>
      </collision>
    </link>
    <link name='secondary_hull_endcaps_v1_2'>
      <pose relative_to='__model__'>0.10099999776482604 0.078125 0.08500000182539201 0 1.2246467991473532e-16 1.5707963267948968</pose>
      <inertial>
        <pose>9.590445319049415e-19 -0.00090163934426229367 -4.3102346894757618e-18 1.224646799147353e-16 1.2325951644078309e-32 -1.5707963267948968</pose>
        <mass>0.2730829414132927</mass>
        <inertia>
          <ixx>0.00042999371348764574</ixx>
          <ixy>4.3368086899420177e-19</ixy>
          <ixz>0</ixz>
          <iyy>0.00022387761772263599</iyy>
          <iyz>0</iyz>
          <izz>0.00022387761772264727</izz>
        </inertia>
      </inertial>
      <visual name='secondary_hull_endcaps_v1_2__body1_visual'>
        <geometry>
          <mesh>
            <scale>0.01 0.01 0.01</scale>
            <uri>meshes/secondary_hull_endcaps_v1_2/body1_visual.obj</uri>
          </mesh>
        </geometry>
      </visual>
      <collision name='secondary_hull_endcaps_v1_2__body1_collision'>
        <pose relative_to='__model__'>0.10099999776482604 0.078125 0.08500000182539201 0 -1.5707963267948966 0</pose>
        <geometry>
          <box>
            <size>0.12 0.12 0.02</size>
          </box>
        </geometry>
      </collision>
    </link>
    <link name='secondary_hull_endcaps_v1_3'>
      <pose relative_to='__model__'>-0.099000002235173953 0.078125 0.08500000182539201 0 0 -1.5707963267948963</pose>
      <inertial>
        <pose>-6.117211279491137e-18 -0.0009016393442622902 0 0 0 1.5707963267948963</pose>
        <mass>0.2730829414132927</mass>
        <inertia>
          <ixx>0.00042999371348764574</ixx>
          <ixy>0</ixy>
          <ixz>0</ixz>
          <iyy>0.00022387761772263599</iyy>
          <iyz>0</iyz>
          <izz>0.00022387761772264727</izz>
        </inertia>
      </inertial>
      <visual name='secondary_hull_endcaps_v1_3__body1_visual'>
        <geometry>
          <mesh>
            <scale>0.01 0.01 0.01</scale>
            <uri>meshes/secondary_hull_endcaps_v1_3/body1_visual.obj</uri>
          </mesh>
        </geometry>
      </visual>
      <collision name='secondary_hull_endcaps_v1_3__body1_collision'>
        <pose relative_to='__model__'>-0.099000002235173953 0.078125 0.08500000182539201 0 -1.5707963267948966 0</pose>
        <geometry>
          <box>
            <size>0.12 0.12 0.02</size>
          </box>
        </geometry>
      </collision>
    </link>
    <link name='secondary_hull_endcaps_v1_4'>
      <pose relative_to='__model__'>0.10099999776482604 -0.078125000000000014 0.08500000182539201 0 1.2246467991473532e-16 1.5707963267948968</pose>
      <inertial>
        <pose>9.590445319049415e-19 -0.00090163934426229627 4.3102346894757556e-18 1.224646799147353e-16 1.2325951644078309e-32 -1.5707963267948968</pose>
        <mass>0.2730829414132927</mass>
        <inertia>
          <ixx>0.00042999371348764531</ixx>
          <ixy>0</ixy>
          <ixz>0</ixz>
          <iyy>0.00022387761772263599</iyy>
          <iyz>2.1684043449710089e-19</iyz>
          <izz>0.000223877617722649</izz>
        </inertia>
      </inertial>
      <visual name='secondary_hull_endcaps_v1_4__body1_visual'>
        <geometry>
          <mesh>
            <scale>0.01 0.01 0.01</scale>
            <uri>meshes/secondary_hull_endcaps_v1_4/body1_visual.obj</uri>
          </mesh>
        </geometry>
      </visual>
      <collision name='secondary_hull_endcaps_v1_4__body1_collision'>
        <pose relative_to='__model__'>0.10099999776482604 -0.078125000000000014 0.08500000182539201 0 -1.5707963267948966 0</pose>
        <geometry>
          <box>
            <size>0.12 0.12 0.02</size>
          </box>
        </geometry>
      </collision>
    </link>
    <link name='thruster_enclosure_v5_5'>
      <pose relative_to='__model__'>0.23500000037252902 -0.14999999999999722 0.14000000136904406 -3.106139814307734e-30 -6.1232339957367734e-17 -1.5707963267948459</pose>
      <inertial>
        <pose>-0.00016404096371551034 -0.016890935437908001 0.010727722238094114 6.1232339957367734e-17 -1.2325951644078309e-32 1.5707963267948459</pose>
        <mass>0.16043165212635116</mass>
        <inertia>
          <ixx>0.00028918540189159115</ixx>
          <ixy>1.0872556777119513e-07</ixy>
          <ixz>-8.7382323868756898e-06</ixz>
          <iyy>0.00029725706691747199</iyy>
          <iyz>1.978532149214153e-07</iyz>
          <izz>0.00042866556663946447</izz>
        </inertia>
      </inertial>
      <visual name='thruster_enclosure_v5_5__body1_visual'>
        <geometry>
          <mesh>
            <scale>0.01 0.01 0.01</scale>
            <uri>meshes/thruster_enclosure_v5_5/body1_visual.obj</uri>
          </mesh>
        </geometry>
      </visual>
      <collision name='thruster_enclosure_v5_5__body1_collision'>
        <pose relative_to='__model__'>0.23125000037252888 -0.15000000000000013 0.14725000136904406 0 -1.5707963267948966 0</pose>
        <geometry>
          <box>
            <size>0.11449999999999999 0.14000000000000024 0.11250000000000025</size>
          </box>
        </geometry>
      </collision>
    </link>
    <link name='thruster_enclosure_v5_6'>
      <pose relative_to='__model__'>0.23500000037252883 0.1500000000000028 0.14000000136904403 -3.1123027901297731e-30 -6.1232339957367722e-17 -1.5707963267948459</pose>
      <inertial>
        <pose>-0.00016404096371551034 -0.016890935437908004 0.010727722238094132 6.1232339957367722e-17 -6.1629758220391547e-33 1.5707963267948459</pose>
        <mass>0.16043165212635116</mass>
        <inertia>
          <ixx>0.00028918540189159202</ixx>
          <ixy>1.0872556777032777e-07</ixy>
          <ixz>-8.7382323868748224e-06</ixz>
          <iyy>0.00029725706691746852</iyy>
          <iyz>1.9785321492184899e-07</iyz>
          <izz>0.00042866556663946447</izz>
        </inertia>
      </inertial>
      <visual name='thruster_enclosure_v5_6__body1_visual'>
        <geometry>
          <mesh>
            <scale>0.01 0.01 0.01</scale>
            <uri>meshes/thruster_enclosure_v5_6/body1_visual.obj</uri>
          </mesh>
        </geometry>
      </visual>
      <collision name='thruster_enclosure_v5_6__body1_collision'>
        <pose relative_to='__model__'>0.23125000037252869 0.14999999999999986 0.14725000136904404 0 -1.5707963267948966 0</pose>
        <geometry>
          <box>
            <size>0.11449999999999999 0.14000000000000024 0.11250000000000025</size>
          </box>
        </geometry>
      </collision>
    </link>
    <link name='thruster_enclosure_v5_7'>
      <pose relative_to='__model__'>-0.23500000484287681 -0.1500000000000028 0.14000000182539196 -3.1123027901297731e-30 -6.1232339957383425e-17 1.5707963267949474</pose>
      <inertial>
        <pose>-0.00016404096371551639 -0.016890935437907963 0.010727722238094104 -6.1232339957383438e-17 0 -1.5707963267949474</pose>
        <mass>0.16043165212635116</mass>
        <inertia>
          <ixx>0.00028918540189159115</ixx>
          <ixy>1.0872556777119513e-07</ixy>
          <ixz>8.7382323868748224e-06</ixz>
          <iyy>0.00029725706691746852</iyy>
          <iyz>-1.9785321492011426e-07</iyz>
          <izz>0.00042866556663946273</izz>
        </inertia>
      </inertial>
      <visual name='thruster_enclosure_v5_7__body1_visual'>
        <geometry>
          <mesh>
            <scale>0.01 0.01 0.01</scale>
            <uri>meshes/thruster_enclosure_v5_7/body1_visual.obj</uri>
          </mesh>
        </geometry>
      </visual>
      <collision name='thruster_enclosure_v5_7__body1_collision'>
        <pose relative_to='__model__'>-0.23125000484287667 -0.14999999999999988 0.14725000182539197 0 -1.5707963267948966 0</pose>
        <geometry>
          <box>
            <size>0.11449999999999999 0.14000000000000029 0.11250000000000025</size>
          </box>
        </geometry>
      </collision>
    </link>
    <link name='thruster_enclosure_v5_8'>
      <pose relative_to='__model__'>-0.23500000484287661 0.14999999999999722 0.14000000182539188 -3.1123027901297731e-30 -6.1232339957411849e-17 1.5707963267949474</pose>
      <inertial>
        <pose>-0.00016404096371551639 -0.016890935437908015 0.010727722238094114 -6.1232339957411849e-17 0 -1.5707963267949474</pose>
        <mass>0.16043165212635116</mass>
        <inertia>
          <ixx>0.00028918540189159375</ixx>
          <ixy>1.0872556777119513e-07</ixy>
          <ixz>8.7382323868748224e-06</ixz>
          <iyy>0.00029725706691746678</iyy>
          <iyz>-1.9785321492228267e-07</iyz>
          <izz>0.0004286655666394662</izz>
        </inertia>
      </inertial>
      <visual name='thruster_enclosure_v5_8__body1_visual'>
        <geometry>
          <mesh>
            <scale>0.01 0.01 0.01</scale>
            <uri>meshes/thruster_enclosure_v5_8/body1_visual.obj</uri>
          </mesh>
        </geometry>
      </visual>
      <collision name='thruster_enclosure_v5_8__body1_collision'>
        <pose relative_to='__model__'>-0.23125000484287647 0.15000000000000013 0.14725000182539189 0 -1.5707963267948966 0</pose>
        <geometry>
          <box>
            <size>0.11449999999999999 0.14000000000000029 0.11250000000000025</size>
          </box>
        </geometry>
      </collision>
    </link>
    <link name='forward_cam_1'>
      <pose relative_to='__model__'>-2.2351740014414647e-09 -0.30499999999999977 0.14749999999999994 1.5707963267948963 0 0</pose>
      <inertial>
        <pose>4.4136049415346879e-14 8.5146920495795758e-18 0.0092274748841152474 -1.5707963267948963 0 0</pose>
        <mass>0.033283293915246544</mass>
        <inertia>
          <ixx>9.0729682929082539e-06</ixx>
          <ixy>-6.2086251095301885e-18</ixy>
          <ixz>-1.2050804987785792e-20</ixz>
          <iyy>1.4735325857890354e-05</iyy>
          <iyz>0</iyz>
          <izz>9.0729682861042348e-06</izz>
        </inertia>
      </inertial>
      <visual name='forward_cam_1__body1_visual'>
        <geometry>
          <mesh>
            <scale>0.01 0.01 0.01</scale>
            <uri>meshes/forward_cam_1/body1_visual.obj</uri>
          </mesh>
        </geometry>
      </visual>
      <collision name='forward_cam_1__body1_collision'>
        <pose relative_to='__model__'>-2.2351740014414647e-09 -0.31749999999999978 0.14749999999999994 0 -1.5707963267948966 0</pose>
        <geometry>
          <box>
            <size>0.059999999999999984 0.025000000000000001 0.059999999999999998</size>
          </box>
        </geometry>
      </collision>
    </link>
    <link name='camera_cover_v1_1'>
      <pose relative_to='__model__'>-2.2351740014414647e-09 -0.32999999999999985 0.14749999999999994 0 0 0</pose>
      <inertial>
        <pose>-4.4131268547979977e-18 -0.00054878048780487854 2.7755575615628914e-17 0 0 0</pose>
        <mass>0.018354755078598368</mass>
        <inertia>
          <ixx>2.6124497970536967e-06</ixx>
          <ixy>-3.6056027419362208e-22</ixy>
          <ixz>-3.2400745373058789e-21</ixz>
          <iyy>4.9300424464160603e-06</iyy>
          <iyz>-2.1684043449710089e-19</iyz>
          <izz>2.6124497970536967e-06</izz>
        </inertia>
      </inertial>
      <visual name='camera_cover_v1_1__body1_visual'>
        <geometry>
          <mesh>
            <scale>0.01 0.01 0.01</scale>
            <uri>meshes/camera_cover_v1_1/body1_visual.obj</uri>
          </mesh>
        </geometry>
      </visual>
      <collision name='camera_cover_v1_1__body1_collision'>
        <pose relative_to='__model__'>-2.2351740014414647e-09 -0.32999999999999985 0.14749999999999994 0 -1.5707963267948966 0</pose>
        <geometry>
          <box>
            <size>0.049999999999999982 0.01 0.050000000000000003</size>
          </box>
        </geometry>
      </collision>
    </link>
    <link name='bottom_cam_1'>
      <pose relative_to='__model__'>-2.2351740014414647e-09 -0.2699999999999998 0.13500000182539199 3.1415926535897931 0 0</pose>
      <inertial>
        <pose>4.4136049415346879e-14 1.540269225393088e-17 0.009227474884115244 -3.1415926535897931 0 0</pose>
        <mass>0.033283293915246544</mass>
        <inertia>
          <ixx>9.0729682929073865e-06</ixx>
          <ixy>1.2050803372198658e-20</ixy>
          <ixz>-6.2086251046834271e-18</ixz>
          <iyy>9.0729682861042348e-06</iyy>
          <iyz>2.1684043449710089e-19</iyz>
          <izz>1.4735325857889812e-05</izz>
        </inertia>
      </inertial>
      <visual name='bottom_cam_1__body1_visual'>
        <geometry>
          <mesh>
            <scale>0.01 0.01 0.01</scale>
            <uri>meshes/bottom_cam_1/body1_visual.obj</uri>
          </mesh>
        </geometry>
      </visual>
      <collision name='bottom_cam_1__body1_collision'>
        <pose relative_to='__model__'>-2.2351740014414647e-09 -0.2699999999999998 0.122500001825392 0 -1.5707963267948966 0</pose>
        <geometry>
          <box>
            <size>0.025000000000000001 0.059999999999999998 0.059999999999999998</size>
          </box>
        </geometry>
      </collision>
    </link>
    <link name='camera_cover_v1_2'>
      <pose relative_to='__model__'>-2.2351740014414647e-09 -0.2699999999999998 0.11000000182539205 1.5707963267948963 0 0</pose>
      <inertial>
        <pose>-4.4131268547979977e-18 -0.00054878048780488114 6.7019543936922309e-18 -1.5707963267948963 0 0</pose>
        <mass>0.018354755078598368</mass>
        <inertia>
          <ixx>2.612449797053263e-06</ixx>
          <ixy>3.240072921718745e-21</ixy>
          <ixz>-3.6055623522578735e-22</ixz>
          <iyy>2.6124497970536154e-06</iyy>
          <iyz>0</iyz>
          <izz>4.9300424464161687e-06</izz>
        </inertia>
      </inertial>
      <visual name='camera_cover_v1_2__body1_visual'>
        <geometry>
          <mesh>
            <scale>0.01 0.01 0.01</scale>
            <uri>meshes/camera_cover_v1_2/body1_visual.obj</uri>
          </mesh>
        </geometry>
      </visual>
      <collision name='camera_cover_v1_2__body1_collision'>
        <pose relative_to='__model__'>-2.2351740014414647e-09 -0.2699999999999998 0.11000000182539205 0 -1.5707963267948966 0</pose>
        <geometry>
          <box>
            <size>0.01 0.050000000000000003 0.050000000000000003</size>
          </box>
        </geometry>
      </collision>
    </link>
    <link name='aft_enclosure_v2_1'>
      <pose relative_to='__model__'>-1.8652000832730663e-10 0.26250000000000001 0.32500000159752884 0 0 0</pose>
      <inertial>
        <pose>0 0.0011724137931033995 0 0 0 0</pose>
        <mass>2.9210921192159591</mass>
        <inertia>
          <ixx>0.012461787389313028</ixx>
          <ixy>1.0368239553354578e-18</ixy>
          <ixz>2.5849394142282115e-26</ixz>
          <iyy>0.024152647278478989</iyy>
          <iyz>0</iyz>
          <izz>0.012461787389312418</izz>
        </inertia>
      </inertial>
      <visual name='aft_enclosure_v2_1__body1_visual'>
        <geometry>
          <mesh>
            <scale>0.01 0.01 0.01</scale>
            <uri>meshes/aft_enclosure_v2_1/body1_visual.obj</uri>
          </mesh>
        </geometry>
      </visual>
      <collision name='aft_enclosure_v2_1__body1_collision'>
        <pose relative_to='__model__'>-1.8652000832730663e-10 0.26250000000000001 0.32500000159752884 0 -1.5707963267948966 0</pose>
        <geometry>
          <box>
            <size>0.27000000000000002 0.040000000000000001 0.27000000000000002</size>
          </box>
        </geometry>
      </collision>
    </link>
    <link name='front_enclosure_updated_v1_1'>
      <pose relative_to='__model__'>-1.8652000832730663e-10 -0.23749999999999999 0.32500000159752884 0 0 0</pose>
      <inertial>
        <pose>-4.9206995197573777e-17 -0.00063739376770538536 1.1102230246251565e-16 0 0 0</pose>
        <mass>1.0535330963813365</mass>
        <inertia>
          <ixx>0.0072431790753459124</ixx>
          <ixy>3.304324822033655e-20</ixy>
          <ixz>0</ixz>
          <iyy>0.014201178462267053</iyy>
          <iyz>-1.3877787807814457e-17</iyz>
          <izz>0.0072431790753455516</izz>
        </inertia>
      </inertial>
      <visual name='front_enclosure_updated_v1_1__body1_visual'>
        <geometry>
          <mesh>
            <scale>0.01 0.01 0.01</scale>
            <uri>meshes/front_enclosure_updated_v1_1/body1_visual.obj</uri>
          </mesh>
        </geometry>
      </visual>
      <collision name='front_enclosure_updated_v1_1__body1_collision'>
        <pose relative_to='__model__'>-1.8652000832730663e-10 -0.23749999999999999 0.32500000159752884 0 -1.5707963267948966 0</pose>
        <geometry>
          <box>
            <size>0.27000000000000002 0.039999999999999966 0.27000000000000002</size>
          </box>
        </geometry>
      </collision>
    </link>
    <link name='front_view_enclosure_v2_1'>
      <pose relative_to='__model__'>-1.8652000832730663e-10 -0.23750000000000021 0.32500000159752884 3.1415926535897931 0 -8.1046280797636465e-14</pose>
      <inertial>
        <pose>1.8337365304116824e-17 0.051432600950118715 -2.0127112738969562e-17 -3.1415926535897931 9.9253068361623089e-30 -8.1046280797636465e-14</pose>
        <mass>1.1804298776414623</mass>
        <inertia>
          <ixx>0.0052190145120671605</ixx>
          <ixy>2.5109644205662697e-16</ixy>
          <ixz>-5.1950337527756785e-18</ixz>
          <iyy>0.0083416203525230465</iyy>
          <iyz>4.163336342344337e-17</iyz>
          <izz>0.0052190145120671189</izz>
        </inertia>
      </inertial>
      <visual name='front_view_enclosure_v2_1__body1_visual'>
        <geometry>
          <mesh>
            <scale>0.01 0.01 0.01</scale>
            <uri>meshes/front_view_enclosure_v2_1/body1_visual.obj</uri>
          </mesh>
        </geometry>
      </visual>
      <collision name='front_view_enclosure_v2_1__body1_collision'>
        <pose relative_to='__model__'>-1.8652000832730663e-10 -0.2925000000000047 0.32500000159752884 0 -1.5707963267948966 0</pose>
        <geometry>
          <box>
            <size>0.22 0.10999999999999108 0.22</size>
          </box>
        </geometry>
      </collision>
    </link>
    <link name='cw_p_v2_1'>
      <pose relative_to='__model__'>0.091571698768572032 -0.21467830085889897 0.075000000858279015 -1.5707963267948968 -0.0036905099172715073 2.3561944901923453</pose>
      <inertial>
        <pose>6.0464328856257854e-15 1.8374949999067081e-14 0.0055648640886395481 -1.5707963267948968 0.78539816339744795 -3.1379021436725218</pose>
        <mass>0.010685972005449422</mass>
        <inertia>
          <ixx>4.7097015469971292e-06</ixx>
          <ixy>1.286947626245649e-06</ixy>
          <ixz>3.4470142940088572e-12</ixz>
          <iyy>4.7097015469984844e-06</iyy>
          <iyz>-3.4470130471763588e-12</iyz>
          <izz>3.4241492437447766e-06</izz>
        </inertia>
      </inertial>
      <visual name='cw_p_v2_1__body1_visual'>
        <geometry>
          <mesh>
            <scale>0.01 0.01 0.01</scale>
            <uri>meshes/cw_p_v2_1/body1_visual.obj</uri>
          </mesh>
        </geometry>
      </visual>
      <collision name='cw_p_v2_1__body1_collision'>
        <pose relative_to='__model__'>0.082732863253852068 -0.22351713476373039 0.075000010126718517 1.5707981283238024 -0.99024053031595616 -0.78539671433160352</pose>
        <geometry>
          <box>
            <size>0.085986396008190621 0.090009944012045318 0.035000000453709962</size>
          </box>
        </geometry>
      </collision>
    </link>
    <link name='cw_p_v2_2'>
      <pose relative_to='__model__'>-0.091571699513629867 -0.21467830085889922 0.075000000974185008 -1.5707963267948961 0.0076411472498130184 -2.3561944901923457</pose>
      <inertial>
        <pose>6.0506070639898546e-15 1.8335810300640354e-14 0.0055648640886395116 -1.5707963267948961 -0.78539816339744761 3.1339515063399794</pose>
        <mass>0.010685972005449422</mass>
        <inertia>
          <ixx>4.7097015813437866e-06</ixx>
          <ixy>-1.2869475919001841e-06</ixy>
          <ixz>-7.7332079135477086e-12</ixz>
          <iyy>4.7097015813424856e-06</iyy>
          <iyz>-7.7332067073727917e-12</iyz>
          <izz>3.4241491750539553e-06</izz>
        </inertia>
      </inertial>
      <visual name='cw_p_v2_2__body1_visual'>
        <geometry>
          <mesh>
            <scale>0.01 0.01 0.01</scale>
            <uri>meshes/cw_p_v2_2/body1_visual.obj</uri>
          </mesh>
        </geometry>
      </visual>
      <collision name='cw_p_v2_2__body1_collision'>
        <pose relative_to='__model__'>-0.082732865683010387 -0.22351713644783114 0.075000010229130179 -3.1415908215959218 -1.0015721874830288 0.78539963803148993</pose>
        <geometry>
          <box>
            <size>0.085986396008190608 0.03500000045370992 0.090009944012045331</size>
          </box>
        </geometry>
      </collision>
    </link>
    <link name='cw_p_v2_3'>
      <pose relative_to='__model__'>-0.23500000484287686 -0.15000000000000277 0.15500000182539173 -1.2671078290112502e-29 -6.1232339957367648e-17 1.5707963267949474</pose>
      <inertial>
        <pose>6.0605907920481369e-15 1.8331699515813811e-14 0.0055648640886394691 -6.1232339957367648e-17 9.5649384758047681e-30 -1.5707963267949474</pose>
        <mass>0.010685972005449422</mass>
        <inertia>
          <ixx>3.424149260721431e-06</ixx>
          <ixy>2.747258258557761e-13</ixy>
          <ixz>-8.1315162936412833e-19</ixz>
          <iyy>3.4227539037755576e-06</iyy>
          <iyz>-7.0473141211557788e-19</iyz>
          <izz>5.9966491732434558e-06</izz>
        </inertia>
      </inertial>
      <visual name='cw_p_v2_3__body1_visual'>
        <geometry>
          <mesh>
            <scale>0.01 0.01 0.01</scale>
            <uri>meshes/cw_p_v2_3/body1_visual.obj</uri>
          </mesh>
        </geometry>
      </visual>
      <collision name='cw_p_v2_3__body1_collision'>
        <pose relative_to='__model__'>-0.23500000568646917 -0.15000001436118363 0.16749999825669032 2.1476616133579691 -1.570794869525326 -1.5707963268139429</pose>
        <geometry>
          <box>
            <size>0.035000007435347001 0.090009944011994442 0.085986396008190608</size>
          </box>
        </geometry>
      </collision>
    </link>
    <link name='cw_p_v2_4'>
      <pose relative_to='__model__'>0.23500000037252883 0.15000000000000269 0.15500000136904402 -6.1232339957354928e-17 3.1029013821918856e-30 5.0674225161936373e-14</pose>
      <inertial>
        <pose>6.0468215398163047e-15 1.8390813877906896e-14 0.0055648640886394691 6.1232339957354928e-17 -6.484508643663091e-43 -5.0674225161936373e-14</pose>
        <mass>0.010685972005449422</mass>
        <inertia>
          <ixx>3.4227539037754492e-06</ixx>
          <ixy>-2.7472588006588472e-13</ixy>
          <ixz>-7.0473141211557788e-19</ixz>
          <iyy>3.4241492607216479e-06</iyy>
          <iyz>8.6736173798840355e-19</iyz>
          <izz>5.9966491732432389e-06</izz>
        </inertia>
      </inertial>
      <visual name='cw_p_v2_4__body1_visual'>
        <geometry>
          <mesh>
            <scale>0.01 0.01 0.01</scale>
            <uri>meshes/cw_p_v2_4/body1_visual.obj</uri>
          </mesh>
        </geometry>
      </visual>
      <collision name='cw_p_v2_4__body1_collision'>
        <pose relative_to='__model__'>0.23500000092154594 0.14999999114156537 0.16750000144354146 0.57686528653537361 -1.5707953788420939 5.8544517758331891e-11</pose>
        <geometry>
          <box>
            <size>0.035000000148995875 0.085986396008190594 0.09000994401204894</size>
          </box>
        </geometry>
      </collision>
    </link>
    <link name='ccw_p_v2_1'>
      <pose relative_to='__model__'>-0.23500000484287661 0.14999999999999727 0.15500000182539206 4.6139834876005686e-24 2.7183456743048246e-16 1.5707963267949474</pose>
      <inertial>
        <pose>9.1983127472773726e-11 -3.8965094181248314e-11 0.0055782343695508626 2.7183456743048246e-16 -4.6139696825347272e-24 -1.5707963267949474</pose>
        <mass>0.010580885311567742</mass>
        <inertia>
          <ixx>3.3400134023879287e-06</ixx>
          <ixy>-6.3112275822119202e-13</ixy>
          <ixz>1.2569155785624453e-15</ixz>
          <iyy>3.3404678337696676e-06</iyy>
          <iyz>1.721713049906981e-16</iyz>
          <izz>5.8298022616206898e-06</izz>
        </inertia>
      </inertial>
      <visual name='ccw_p_v2_1__body1_visual'>
        <geometry>
          <mesh>
            <scale>0.01 0.01 0.01</scale>
            <uri>meshes/ccw_p_v2_1/body1_visual.obj</uri>
          </mesh>
        </geometry>
      </visual>
      <collision name='ccw_p_v2_1__body1_collision'>
        <pose relative_to='__model__'>-0.23500000484017286 0.14999999995135124 0.16750000188156894 -0.59918055777179702 -1.5707963267948966 0</pose>
        <geometry>
          <box>
            <size>0.035000000185669469 0.09000993675289648 0.085450490845673771</size>
          </box>
        </geometry>
      </collision>
    </link>
    <link name='ccw_p_v2_2'>
      <pose relative_to='__model__'>0.091571698768571824 0.21467830085889938 0.074999998717279026 -1.5707963267948959 -1.8873791418627661e-15 0.78539816339744639</pose>
      <inertial>
        <pose>9.1983124102038437e-11 -3.8965091675300816e-11 0.0055782343695508513 1.5707963267948957 0.7853981633974465 1.1775693440128292e-15</pose>
        <mass>0.010580885311567742</mass>
        <inertia>
          <ixx>4.5851350475228448e-06</ixx>
          <ixy>-1.2446672139254569e-06</ixy>
          <ixz>-4.4716000921572047e-13</ixz>
          <iyy>4.5851350478672145e-06</iyy>
          <iyz>-4.453823919912947e-13</iyz>
          <izz>3.3400134023879287e-06</izz>
        </inertia>
      </inertial>
      <visual name='ccw_p_v2_2__body1_visual'>
        <geometry>
          <mesh>
            <scale>0.01 0.01 0.01</scale>
            <uri>meshes/ccw_p_v2_2/body1_visual.obj</uri>
          </mesh>
        </geometry>
      </visual>
      <collision name='ccw_p_v2_2__body1_collision'>
        <pose relative_to='__model__'>0.082732863898857062 0.22351713555551173 0.074999998611984225 -1.5707963058354446 -0.97161576902315239 0.78539819366926678</pose>
        <geometry>
          <box>
            <size>0.085450490845673799 0.09000993675289648 0.035000000246173391</size>
          </box>
        </geometry>
      </collision>
    </link>
    <link name='ccw_p_v2_3'>
      <pose relative_to='__model__'>0.23500000037252891 -0.14999999999999719 0.15500000136904402 4.6139834876005686e-24 2.7183456743053299e-16 -1.5707963267948459</pose>
      <inertial>
        <pose>9.1983104071264399e-11 -3.8965051488683935e-11 0.0055782343695508626 -2.7183456743053299e-16 4.6139697318385338e-24 1.5707963267948459</pose>
        <mass>0.010580885311567742</mass>
        <inertia>
          <ixx>3.3400134023881456e-06</ixx>
          <ixy>-6.3112275822119202e-13</ixy>
          <ixz>-1.2569697886710696e-15</ixz>
          <iyy>3.3404678337697761e-06</iyy>
          <iyz>-1.7211709488207383e-16</iyz>
          <izz>5.8298022616206898e-06</izz>
        </inertia>
      </inertial>
      <visual name='ccw_p_v2_3__body1_visual'>
        <geometry>
          <mesh>
            <scale>0.01 0.01 0.01</scale>
            <uri>meshes/ccw_p_v2_3/body1_visual.obj</uri>
          </mesh>
        </geometry>
      </visual>
      <collision name='ccw_p_v2_3__body1_collision'>
        <pose relative_to='__model__'>0.23500000036982521 -0.14999999995135119 0.1675000014252209 -0.5991805577717968 -1.5707963267948966 0</pose>
        <geometry>
          <box>
            <size>0.03500000018566949 0.090009936752896424 0.085450490845673827</size>
          </box>
        </geometry>
      </collision>
    </link>
    <link name='ccw_p_v2_4'>
      <pose relative_to='__model__'>-0.10571383513736066 0.20053616523516823 0.074999998717278957 -1.5707963267948948 -2.2759572004815709e-15 -0.78539816339744717</pose>
      <inertial>
        <pose>9.1983115774002383e-11 -3.8965050385900294e-11 0.0055782343695508392 1.5707963267948934 -0.78539816339744728 4.3177542613803761e-15</pose>
        <mass>0.010580885311567742</mass>
        <inertia>
          <ixx>4.5851350478671874e-06</ixx>
          <ixy>1.2446672139255111e-06</ixy>
          <ixz>-4.4538236488624039e-13</ixz>
          <iyy>4.5851350475230616e-06</iyy>
          <iyz>4.4715994145308469e-13</iyz>
          <izz>3.3400134023880371e-06</izz>
        </inertia>
      </inertial>
      <visual name='ccw_p_v2_4__body1_visual'>
        <geometry>
          <mesh>
            <scale>0.01 0.01 0.01</scale>
            <uri>meshes/ccw_p_v2_4/body1_visual.obj</uri>
          </mesh>
        </geometry>
      </visual>
      <collision name='ccw_p_v2_4__body1_collision'>
        <pose relative_to='__model__'>-0.096875000440748454 0.20937500010488308 0.07499999861198417 -3.1415926326303434 -0.97161576902315272 -0.78539813312562901</pose>
        <geometry>
          <box>
            <size>0.085450490845673771 0.035000000246173425 0.090009936752896438</size>
          </box>
        </geometry>
      </collision>
    </link>
    <joint name='rigid_1' type='fixed'>
      <parent>base_link_1</parent>
      <child>base_structure_v3_1</child>
      <axis>
        <xyz>0 0 1</xyz>
        <limit>
          <lower>-inf</lower>
          <upper>inf</upper>
        </limit>
      </axis>
    </joint>
    <joint name='rigid_2' type='fixed'>
      <pose relative_to='__model__'>0.012500000000000001 -0.14999999999999999 -0.012500000000000001 0 0 0</pose>
      <parent>base_structure_v3_1</parent>
      <child>aft_support_1</child>
      <axis>
        <xyz>0 0 1</xyz>
        <limit>
          <lower>-inf</lower>
          <upper>inf</upper>
        </limit>
      </axis>
    </joint>
    <joint name='rigid_3' type='fixed'>
      <pose relative_to='__model__'>0.14999999878276843 -0.29999999999999999 0.012499999999999997 0 0 0</pose>
      <parent>base_structure_v3_1</parent>
      <child>aft_support_2</child>
      <axis>
        <xyz>0 0 1</xyz>
        <limit>
          <lower>-inf</lower>
          <upper>inf</upper>
        </limit>
      </axis>
    </joint>
    <joint name='rigid_4' type='fixed'>
      <pose relative_to='__model__'>-0.075000002235174001 0 0.13000000182539201 0 0 0</pose>
      <parent>base_structure_v3_1</parent>
      <child>lower_mounts_v4_1</child>
      <axis>
        <xyz>0 0 1</xyz>
        <limit>
          <lower>-inf</lower>
          <upper>inf</upper>
        </limit>
      </axis>
    </joint>
    <joint name='rigid_5' type='fixed'>
      <pose relative_to='__model__'>0.075000001490116291 0 0.13000000182539201 0 0 0</pose>
      <parent>base_structure_v3_1</parent>
      <child>lower_mounts_v4_2</child>
      <axis>
        <xyz>0 0 1</xyz>
        <limit>
          <lower>-inf</lower>
          <upper>inf</upper>
        </limit>
      </axis>
    </joint>
    <joint name='rigid_6' type='fixed'>
      <pose relative_to='__model__'>0.096874999627471078 -0.20937500000000001 0.13000000085827901 0 0 0</pose>
      <parent>base_structure_v3_1</parent>
      <child>thruster_enclosure_v5_1</child>
      <axis>
        <xyz>0 0 1</xyz>
        <limit>
          <lower>-inf</lower>
          <upper>inf</upper>
        </limit>
      </axis>
    </joint>
    <joint name='rigid_7' type='fixed'>
      <pose relative_to='__model__'>-0.096875000372528955 -0.20937500000000006 0.13000000097418499 0 0 0</pose>
      <parent>base_structure_v3_1</parent>
      <child>thruster_enclosure_v5_2</child>
      <axis>
        <xyz>0 0 1</xyz>
        <limit>
          <lower>-inf</lower>
          <upper>inf</upper>
        </limit>
      </axis>
    </joint>
    <joint name='rigid_10' type='fixed'>
      <pose relative_to='__model__'>0.00099999776482604828 -0.078125000000000028 0.08500000182539201 0 0 0</pose>
      <parent>lower_mounts_v4_1</parent>
      <child>batt_hull_2_1</child>
      <axis>
        <xyz>0 0 1</xyz>
        <limit>
          <lower>-inf</lower>
          <upper>inf</upper>
        </limit>
      </axis>
    </joint>
    <joint name='rigid_11' type='fixed'>
      <pose relative_to='__model__'>0.00099999776482604828 0.078125000000000014 0.08500000182539201 0 0 0</pose>
      <parent>lower_mounts_v4_1</parent>
      <child>batt_hull_v1_1</child>
      <axis>
        <xyz>0 0 1</xyz>
        <limit>
          <lower>-inf</lower>
          <upper>inf</upper>
        </limit>
      </axis>
    </joint>
    <joint name='rigid_12' type='fixed'>
      <pose relative_to='__model__'>0.096874999627471037 0.20937499999999998 0.12999999871727896 0 0 0</pose>
      <parent>base_structure_v3_1</parent>
      <child>thruster_enclosure_v5_4</child>
      <axis>
        <xyz>0 0 1</xyz>
        <limit>
          <lower>-inf</lower>
          <upper>inf</upper>
        </limit>
      </axis>
    </joint>
    <joint name='rigid_13' type='fixed'>
      <pose relative_to='__model__'>-0.096875000372528927 0.20937500000000003 0.12999999871727894 0 0 0</pose>
      <parent>base_structure_v3_1</parent>
      <child>thruster_enclosure_v5_3</child>
      <axis>
        <xyz>0 0 1</xyz>
        <limit>
          <lower>-inf</lower>
          <upper>inf</upper>
        </limit>
      </axis>
    </joint>
    <joint name='rigid_14' type='fixed'>
      <pose relative_to='__model__'>-1.8652000832730663e-10 -0.012500000000000001 0.16000000159752886 0 0 0</pose>
      <parent>base_structure_v3_1</parent>
      <child>main_hull_mounts_v2_1</child>
      <axis>
        <xyz>0 0 1</xyz>
        <limit>
          <lower>-inf</lower>
          <upper>inf</upper>
        </limit>
      </axis>
    </joint>
    <joint name='rigid_15' type='fixed'>
      <pose relative_to='__model__'>0.14999999981365034 -0.13125000000000001 0.16000000182539204 0 0 0</pose>
      <parent>base_structure_v3_1</parent>
      <child>main_hull_mounts_v2_2</child>
      <axis>
        <xyz>0 0 1</xyz>
        <limit>
          <lower>-inf</lower>
          <upper>inf</upper>
        </limit>
      </axis>
    </joint>
    <joint name='rigid_16' type='fixed'>
      <pose relative_to='__model__'>0.14999999981365034 0.13125000000000003 0.16000000182539204 0 0 0</pose>
      <parent>base_structure_v3_1</parent>
      <child>main_hull_mounts_v2_3</child>
      <axis>
        <xyz>0 0 1</xyz>
        <limit>
          <lower>-inf</lower>
          <upper>inf</upper>
        </limit>
      </axis>
    </joint>
    <joint name='rigid_17' type='fixed'>
      <pose relative_to='__model__'>-1.8652000832730663e-10 0.26250000000000001 0.32500000159752884 0 0 0</pose>
      <parent>main_hull_mounts_v2_1</parent>
      <child>main_hull_v2_1</child>
      <axis>
        <xyz>0 0 1</xyz>
        <limit>
          <lower>-inf</lower>
          <upper>inf</upper>
        </limit>
      </axis>
    </joint>
    <joint name='rigid_18' type='fixed'>
      <pose relative_to='__model__'>0.10099999776482604 -0.078125000000000014 0.08500000182539201 0 0 0</pose>
      <parent>batt_hull_2_1</parent>
      <child>secondary_hull_endcaps_v1_4</child>
      <axis>
        <xyz>0 0 1</xyz>
        <limit>
          <lower>-inf</lower>
          <upper>inf</upper>
        </limit>
      </axis>
    </joint>
    <joint name='rigid_19' type='fixed'>
      <pose relative_to='__model__'>0.10099999776482604 0.078125 0.08500000182539201 0 0 0</pose>
      <parent>batt_hull_v1_1</parent>
      <child>secondary_hull_endcaps_v1_2</child>
      <axis>
        <xyz>0 0 1</xyz>
        <limit>
          <lower>-inf</lower>
          <upper>inf</upper>
        </limit>
      </axis>
    </joint>
    <joint name='rigid_20' type='fixed'>
      <pose relative_to='__model__'>-0.099000002235173953 0.078125 0.08500000182539201 0 0 0</pose>
      <parent>batt_hull_v1_1</parent>
      <child>secondary_hull_endcaps_v1_3</child>
      <axis>
        <xyz>0 0 1</xyz>
        <limit>
          <lower>-inf</lower>
          <upper>inf</upper>
        </limit>
      </axis>
    </joint>
    <joint name='rigid_21' type='fixed'>
      <pose relative_to='__model__'>-0.099000002235173953 -0.078125000000000042 0.08500000182539201 0 0 0</pose>
      <parent>batt_hull_2_1</parent>
      <child>secondary_hull_endcaps_v1_1</child>
      <axis>
        <xyz>0 0 1</xyz>
        <limit>
          <lower>-inf</lower>
          <upper>inf</upper>
        </limit>
      </axis>
    </joint>
    <joint name='rigid_22' type='fixed'>
      <pose relative_to='__model__'>0.18000000037252925 -0.14999999999999999 0.14750000136904404 0 0 0</pose>
      <parent>base_structure_v3_1</parent>
      <child>thruster_enclosure_v5_5</child>
      <axis>
        <xyz>0 0 1</xyz>
        <limit>
          <lower>-inf</lower>
          <upper>inf</upper>
        </limit>
      </axis>
    </joint>
    <joint name='rigid_23' type='fixed'>
      <pose relative_to='__model__'>0.18000000037252911 0.14999999999999999 0.14750000136904404 0 0 0</pose>
      <parent>base_structure_v3_1</parent>
      <child>thruster_enclosure_v5_6</child>
      <axis>
        <xyz>0 0 1</xyz>
        <limit>
          <lower>-inf</lower>
          <upper>inf</upper>
        </limit>
      </axis>
    </joint>
    <joint name='rigid_24' type='fixed'>
      <pose relative_to='__model__'>-0.18000000484287709 -0.15000000000000002 0.14750000182539194 0 0 0</pose>
      <parent>base_structure_v3_1</parent>
      <child>thruster_enclosure_v5_7</child>
      <axis>
        <xyz>0 0 1</xyz>
        <limit>
          <lower>-inf</lower>
          <upper>inf</upper>
        </limit>
      </axis>
    </joint>
    <joint name='rigid_25' type='fixed'>
      <pose relative_to='__model__'>-0.18000000484287682 0.15000000000000002 0.14750000182539189 0 0 0</pose>
      <parent>base_structure_v3_1</parent>
      <child>thruster_enclosure_v5_8</child>
      <axis>
        <xyz>0 0 1</xyz>
        <limit>
          <lower>-inf</lower>
          <upper>inf</upper>
        </limit>
      </axis>
    </joint>
    <joint name='rigid_26' type='fixed'>
      <pose relative_to='__model__'>-2.2351740014414647e-09 -0.30999999999999978 0.14749999999999994 0 0 0</pose>
      <parent>base_structure_v3_1</parent>
      <child>forward_cam_1</child>
      <axis>
        <xyz>0 0 1</xyz>
        <limit>
          <lower>-inf</lower>
          <upper>inf</upper>
        </limit>
      </axis>
    </joint>
    <joint name='rigid_27' type='fixed'>
      <pose relative_to='__model__'>-2.2351740014414647e-09 -0.32999999999999985 0.14749999999999994 0 0 0</pose>
      <parent>forward_cam_1</parent>
      <child>camera_cover_v1_1</child>
      <axis>
        <xyz>0 0 1</xyz>
        <limit>
          <lower>-inf</lower>
          <upper>inf</upper>
        </limit>
      </axis>
    </joint>
    <joint name='rigid_28' type='fixed'>
      <pose relative_to='__model__'>-2.2351740014414647e-09 -0.2699999999999998 0.13000000182539204 0 0 0</pose>
      <parent>base_structure_v3_1</parent>
      <child>bottom_cam_1</child>
      <axis>
        <xyz>0 0 1</xyz>
        <limit>
          <lower>-inf</lower>
          <upper>inf</upper>
        </limit>
      </axis>
    </joint>
    <joint name='rigid_29' type='fixed'>
      <pose relative_to='__model__'>-2.2351740014414647e-09 -0.2699999999999998 0.11000000182539205 0 0 0</pose>
      <parent>bottom_cam_1</parent>
      <child>camera_cover_v1_2</child>
      <axis>
        <xyz>0 0 1</xyz>
        <limit>
          <lower>-inf</lower>
          <upper>inf</upper>
        </limit>
      </axis>
    </joint>
    <joint name='rigid_38' type='fixed'>
      <pose relative_to='__model__'>-1.8652000832730663e-10 0.26250000000000001 0.32500000159752884 0 0 0</pose>
      <parent>main_hull_v2_1</parent>
      <child>aft_enclosure_v2_1</child>
      <axis>
        <xyz>0 0 1</xyz>
        <limit>
          <lower>-inf</lower>
          <upper>inf</upper>
        </limit>
      </axis>
    </joint>
    <joint name='rigid_39' type='fixed'>
      <pose relative_to='__model__'>-1.8652000832730663e-10 -0.23749999999999999 0.32500000159752884 0 0 0</pose>
      <parent>main_hull_v2_1</parent>
      <child>front_enclosure_updated_v1_1</child>
      <axis>
        <xyz>0 0 1</xyz>
        <limit>
          <lower>-inf</lower>
          <upper>inf</upper>
        </limit>
      </axis>
    </joint>
    <joint name='rigid_40' type='fixed'>
      <pose relative_to='__model__'>-1.8652000832730663e-10 -0.23750000000000018 0.32500000159752884 0 0 0</pose>
      <parent>front_enclosure_updated_v1_1</parent>
      <child>front_view_enclosure_v2_1</child>
      <axis>
        <xyz>0 0 1</xyz>
        <limit>
          <lower>-inf</lower>
          <upper>inf</upper>
        </limit>
      </axis>
    </joint>
    <joint name='forward_port' type='continuous'>
      <pose relative_to='__model__'>0.091571698768572032 -0.21467830085889897 0.075000000858279028 0 0 0</pose>
      <parent>thruster_enclosure_v5_1</parent>
      <child>cw_p_v2_1</child>
      <axis>
        <xyz expressed_in='__model__'>-0.70710678118654757 -0.70710678118654746 0</xyz>
        <limit>
          <lower>-inf</lower>
          <upper>inf</upper>
        </limit>
      </axis>
    </joint>
    <joint name='forward_sb' type='continuous'>
      <pose relative_to='__model__'>-0.09157169951362984 -0.21467830085889919 0.075000000974185008 0 0 0</pose>
      <parent>thruster_enclosure_v5_2</parent>
      <child>cw_p_v2_2</child>
      <axis>
        <xyz expressed_in='__model__'>0.70710678118654735 -0.70710678118654768 -2.5563721649793421e-16</xyz>
        <limit>
          <lower>-inf</lower>
          <upper>inf</upper>
        </limit>
      </axis>
    </joint>
    <joint name='heave_aft_port' type='continuous'>
      <pose relative_to='__model__'>0.23500000037252883 0.15000000000000269 0.15500000136904402 0 0 0</pose>
      <parent>thruster_enclosure_v5_6</parent>
      <child>cw_p_v2_4</child>
      <axis>
        <xyz expressed_in='__model__'>0 6.1232339957367562e-17 0.99999999999999734</xyz>
        <limit>
          <lower>-inf</lower>
          <upper>inf</upper>
        </limit>
      </axis>
    </joint>
    <joint name='heave_forward_sb' type='continuous'>
      <pose relative_to='__model__'>-0.23500000484287686 -0.15000000000000274 0.15500000182539173 0 0 0</pose>
      <parent>thruster_enclosure_v5_7</parent>
      <child>cw_p_v2_3</child>
      <axis>
        <xyz expressed_in='__model__'>-2.2088105346188331e-29 -6.1232339957367512e-17 0.99999999999999756</xyz>
        <limit>
          <lower>-inf</lower>
          <upper>inf</upper>
        </limit>
      </axis>
    </joint>
    <joint name='aft_port' type='continuous'>
      <pose relative_to='__model__'>0.091571698768571796 0.21467830085889936 0.074999998717279026 0 0 0</pose>
      <parent>thruster_enclosure_v5_4</parent>
      <child>ccw_p_v2_2</child>
      <axis>
        <xyz expressed_in='__model__'>-0.70710678118654535 0.70710678118654768 8.047287542164633e-16</xyz>
        <limit>
          <lower>-inf</lower>
          <upper>inf</upper>
        </limit>
      </axis>
    </joint>
    <joint name='aft_sb' type='continuous'>
      <pose relative_to='__model__'>-0.10571383513736064 0.20053616523516818 0.074999998717278957 0 0 0</pose>
      <parent>thruster_enclosure_v5_3</parent>
      <child>ccw_p_v2_4</child>
      <axis>
        <xyz expressed_in='__model__'>-0.70710678118654524 -0.70710678118654691 -2.0489350643965765e-15</xyz>
        <limit>
          <lower>-inf</lower>
          <upper>inf</upper>
        </limit>
      </axis>
    </joint>
    <joint name='heave_aft_sb' type='continuous'>
      <pose relative_to='__model__'>-0.23500000484287661 0.14999999999999727 0.15500000182539206 0 0 0</pose>
      <parent>thruster_enclosure_v5_8</parent>
      <child>ccw_p_v2_1</child>
      <axis>
        <xyz expressed_in='__model__'>0 -6.1232339957367562e-17 0.99999999999999822</xyz>
        <limit>
          <lower>-inf</lower>
          <upper>inf</upper>
        </limit>
      </axis>
    </joint>
    <joint name='heave_forward_port' type='continuous'>
      <pose relative_to='__model__'>0.23500000037252891 -0.14999999999999719 0.15500000136904402 0 0 0</pose>
      <parent>thruster_enclosure_v5_5</parent>
      <child>ccw_p_v2_3</child>
      <axis>
        <xyz expressed_in='__model__'>0 6.1232339957367574e-17 0.99999999999999734</xyz>
        <limit>
          <lower>-inf</lower>
          <upper>inf</upper>
        </limit>
      </axis>
    </joint>
    <joint name='base_link_joint' type='fixed'>
      <parent>base_link</parent>
      <child>base_link_1</child>
      <axis>
        <xyz>0 0 1</xyz>
        <limit>
          <lower>-inf</lower>
          <upper>inf</upper>
        </limit>
      </axis>
    </joint>
  </model>
</sdf>
